<?xml version="1.0"?>

<robot name="Roid1">

  <material name="dark_gray">
    <color rgba="0.2 0.2 0.2 1.0"/>
  </material>
  <material name="light_gray">
    <color rgba="0.99 0.99 0.99 1.0"/>
  </material>
  <material name="light_blue">
    <color rgba="0.3 0.5 1.0 1.0"/>
  </material>
  <material name="orange">
    <color rgba="1.0 0.3 0.1 1.0"/>
  </material>


  <!--base link: origin of this model(0,0,0) -->
  <link name="base_link">
  </link>


  <!--center of body-->
  
  <!--waist-->
  <joint name="c_waist_fixed" type="fixed">
    <parent link="base_link"/>
    <child link="c_waist"/>
    <origin xyz="0 0 0.278106"/>
  </joint>
  <link name="c_waist">
    <visual>
      <geometry>
        <mesh filename="package://roid1_description/meshes/c_waist.stl" />
      </geometry>
      <origin xyz="0 0 0"/>
      <material name="dark_gray"/>
    </visual>
  </link>

  <!--chest-->
  <joint name="c_chest_yaw" type="revolute">
    <parent link="c_waist"/>
    <child link="c_chest"/>
    <axis xyz="0 0 1"/>
    <origin xyz="0 0 0.065192"/>
    <limit lower="-3" upper="3" effort="0" velocity="0"/>
  </joint>
  <link name="c_chest">
    <visual>
      <geometry>
        <mesh filename="package://roid1_description/meshes/c_chest_a.stl" />
      </geometry>
      <origin xyz="0 0 0"/>
      <material name="light_gray"/>
    </visual>
    <visual>
      <geometry>
        <mesh filename="package://roid1_description/meshes/c_chest_b.stl" />
      </geometry>
      <origin xyz="0 0 0"/>
      <material name="dark_gray"/>
    </visual>
  </link>

  <!--head-->
  <joint name="c_head_yaw" type="revolute">
    <parent link="c_chest"/>
    <child link="c_head" />
    <axis xyz="0 0 1"/>
    <origin xyz="0 0 0.039505"/>
    <limit lower="-3" upper="3" effort="0" velocity="0"/>
  </joint>
  <link name="c_head">
    <visual>
      <geometry>
        <mesh filename="package://roid1_description/meshes/c_head_a.stl" />
      </geometry>
      <origin xyz="0 0 0"/>
      <material name="light_gray" />
    </visual>
    <visual>
      <geometry>
        <mesh filename="package://roid1_description/meshes/c_head_b.stl" />
      </geometry>
      <origin xyz="0 0 0"/>
      <material name="light_blue"/>
    </visual>
  </link>


  <!--left side upper body-->

  <!--chest to l_shoulder-->
  <joint name="l_shoulder_pitch" type="revolute">
    <parent link="c_chest"/>
    <child link="l_shoulder" />
    <axis xyz="0 1 0"/>
    <origin xyz="0 0.074375 0"/>
    <limit lower="-3" upper="3" effort="0" velocity="0"/>
  </joint>
  <link name="l_shoulder">
    <visual>
      <geometry>
        <mesh filename="package://roid1_description/meshes/l_shoulder.stl" />
      </geometry>
      <origin xyz="0 0 0"/>
      <material name="light_gray">
          s<color rgba="0.8 0.8 0.8 1"/>
      </material>
    </visual>
    <visual>
      <geometry>
        <mesh filename="package://roid1_description/meshes/dec_shoulderpoint.stl" />
      </geometry>
      <origin xyz="0 0 0"/>
      <material name="orange"/>
    </visual>
  </link>

  <!--l_shoulder_roll-->
  <joint name="l_shoulder_roll" type="revolute">
    <parent link="l_shoulder"/>
    <child link="l_upperarm"/>
    <axis xyz="1 0 0"/>
    <origin xyz="0 0 0"/>
    <limit lower="-3" upper="3" effort="0" velocity="0"/>
  </joint>
  <link name="l_upperarm">
    <visual>
      <geometry>
        <mesh filename="package://roid1_description/meshes/l_arm_upper.stl" />
      </geometry>
      <origin xyz="0 0 0"/>
      <material name="dark_gray" />
    </visual>
  </link>

  <!--l_elbow_yaw-->
  <joint name="l_elbow_yaw" type="revolute">
    <parent link="l_upperarm"/>
    <child link="l_elbow"/>
    <axis xyz="0 0 1"/>
    <origin xyz="0.004449 0 -0.087511"/>
    <limit lower="-3" upper="3" effort="0" velocity="0"/>
  </joint>
  <link name="l_elbow">
    <visual>
      <geometry>
        <mesh filename="package://roid1_description/meshes/l_elbow.stl" />
      </geometry>
      <origin xyz="0.0 0 0"/>
      <material name="dark_gray" />
    </visual>
  </link>

  <!--l_elbow_pitch-->
  <joint name="l_elbow_pitch" type="revolute">
    <parent link="l_elbow"/>
    <child link="l_lowerarm"/>
    <axis xyz="0 1 0"/>
    <origin xyz="0.004698 0 0"/>
    <limit lower="-3" upper="3" effort="0" velocity="0"/>
  </joint>
  <link name="l_lowerarm">
    <visual>
      <geometry>
        <mesh filename="package://roid1_description/meshes/l_arm_lower.stl" />
      </geometry>
      <origin xyz="0 0 0"/>
      <material name="light_gray"/>
    </visual>
  </link>


  <!--right side upper body-->

  <!--r_shoulder_pitch-->
  <joint name="r_shoulder_pitch" type="revolute">
    <parent link="c_chest"/>
    <child link="r_shoulder" />
    <axis xyz="0 1 0"/>
    <origin xyz="0 -0.074375 0"/>
    <limit lower="-3" upper="3" effort="0" velocity="0"/>
  </joint>
  <link name="r_shoulder">
    <visual>
      <geometry>
        <mesh filename="package://roid1_description/meshes/r_shoulder.stl" />
      </geometry>
      <origin xyz="0 0 0"/>
      <material name="light_gray">
          <color rgba="0.8 0.8 0.8 1"/>
      </material>
    </visual>
    <visual>
      <geometry>
        <mesh filename="package://roid1_description/meshes/dec_shoulderpoint.stl" />
      </geometry>
      <origin xyz="0 0 0"/>
      <material name="orange"/>
    </visual>
  </link>

  <!--r_shoulder_roll-->
  <joint name="r_shoulder_roll" type="revolute">
    <parent link="r_shoulder"/>
    <child link="r_upperarm"/>
    <axis xyz="1 0 0"/>
    <origin xyz="0 0 0"/>
    <limit lower="-3" upper="3" effort="0" velocity="0"/>
  </joint>
  <link name="r_upperarm">
    <visual>
      <geometry>
        <mesh filename="package://roid1_description/meshes/r_arm_upper.stl" />
      </geometry>
      <origin xyz="0 0 0"/>
      <material name="dark_gray" />
    </visual>
  </link>

  <!--r_elbow_yaw-->
  <joint name="r_elbow_yaw" type="revolute">
    <parent link="r_upperarm"/>
    <child link="r_elbow"/>
    <axis xyz="0 0 1"/>
    <origin xyz="0.004449 0 -0.087511"/>
    <limit lower="-3" upper="3" effort="0" velocity="0"/>
  </joint>
  <link name="r_elbow">
    <visual>
      <geometry>
        <mesh filename="package://roid1_description/meshes/r_elbow.stl" />
      </geometry>
      <origin xyz="0.0 0 0"/>
      <material name="dark_gray" />
    </visual>
  </link>

  <!--r_elbow_pitch-->
  <joint name="r_elbow_pitch" type="revolute">
    <parent link="r_elbow"/>
    <child link="r_lowerarm"/>
    <axis xyz="0 1 0"/>
    <origin xyz="0.004698 0 0"/>
    <limit lower="-3" upper="3" effort="0" velocity="0"/>
  </joint>
  <link name="r_lowerarm">
    <visual>
      <geometry>
        <mesh filename="package://roid1_description/meshes/r_arm_lower.stl" />
      </geometry>
      <origin xyz="0 0 0"/>
      <material name="light_gray"/>
    </visual>
  </link>


  <!--left side lower body-->

  <!--l_hipjoint_yaw-->
  <joint name="l_hipjoint_yaw" type="revolute">
    <parent link="c_waist"/>
    <child link="l_hipjoint_upper"/>
    <axis xyz="0 0 1"/>
    <origin xyz="0.0 0.021530 -0.044936"/>
    <limit lower="-3" upper="3" effort="0" velocity="0"/>
  </joint>
  <link name="l_hipjoint_upper">
    <visual>
      <geometry>
        <mesh filename="package://roid1_description/meshes/l_hipjoint_upper.stl" />
      </geometry>
      <origin xyz="0 0 0"/>
      <material name="light_gray" />
    </visual>
    <visual>
      <geometry>
        <mesh filename="package://roid1_description/meshes/dec_l_hipjoint_upperpoint.stl" />
      </geometry>
      <origin xyz="0 0 0"/>
      <material name="orange"/>
    </visual>
  </link>

  <!--l_hipjoint_roll-->
  <joint name="l_hipjoint_roll" type="revolute">
    <parent link="l_hipjoint_upper"/>
    <child link="l_hipjoint_lower"/>
    <axis xyz="1 0 0"/>
    <origin xyz="0 -0.004501 0"/>
    <limit lower="-3" upper="3" effort="0" velocity="0"/>
  </joint>
  <link name="l_hipjoint_lower">
    <visual>
      <geometry>
        <mesh filename="package://roid1_description/meshes/l_hipjoint_lower.stl" />
      </geometry>
      <origin xyz="0 0 0"/>
      <material name="dark_gray" />
    </visual>
  </link>

  <!--l_hipjoint_pitch-->
  <joint name="l_hipjoint_pitch" type="revolute">
    <parent link="l_hipjoint_lower"/>
    <child link="l_leg_upper"/>
    <axis xyz="0 1 0"/>
    <origin xyz="0.004052 0.011504 -0.038476"/>
    <limit lower="-3" upper="3" effort="0" velocity="0"/>
  </joint>
  <link name="l_leg_upper">
    <visual>
      <geometry>
        <mesh filename="package://roid1_description/meshes/l_leg_upper_a.stl"/>
      </geometry>
      <origin xyz="0 0 0"/>
      <material name="dark_gray" />
    </visual>
    <visual>
      <geometry>
        <mesh filename="package://roid1_description/meshes/l_leg_upper_b.stl"/>
      </geometry>
      <origin xyz="0 0 0"/>
      <material name="light_gray" />
    </visual>
  </link>

  <!--l_knee_pitch-->
  <joint name="l_knee_pitch" type="revolute">
    <parent link="l_leg_upper"/>
    <child link="l_leg_lower"/>
    <axis xyz="0 1 0"/>
    <origin xyz="0.0 0.0 -0.065008"/>
    <limit lower="-3" upper="3" effort="0" velocity="0"/>
  </joint>
  <link name="l_leg_lower">
    <visual>
      <geometry>
        <mesh filename="package://roid1_description/meshes/l_leg_lower_a.stl"/>
      </geometry>
      <origin xyz="0 0 0"/>
      <material name="dark_gray"/>
    </visual>
    <visual>
      <geometry>
        <mesh filename="package://roid1_description/meshes/l_leg_lower_b.stl"/>
      </geometry>
      <origin xyz="0 0 0"/>
      <material name="light_gray"/>
    </visual>
  </link>

  <!--l_ankle_pitch-->
  <joint name="l_ankle_pitch" type="revolute">
    <parent link="l_leg_lower"/>
    <child link="l_ankle"/>
    <axis xyz="0 1 0"/>
    <origin xyz="0.0 0.0 -0.065203"/>
    <limit lower="-3" upper="3" effort="0" velocity="0"/>
  </joint>
  <link name="l_ankle">
    <visual>
      <geometry>
        <mesh filename="package://roid1_description/meshes/l_ankle.stl" />
      </geometry>
      <origin xyz="0 0 0"/>
      <material name="dark_gray"/>
    </visual>
  </link>

  <!--l_ankle_roll-->
  <joint name="l_ankle_roll" type="revolute">
    <parent link="l_ankle"/>
    <child link="l_foot_large"/>
    <axis xyz="1 0 0"/>
    <origin xyz="0.0 -0.011404 -0.038550"/>
    <limit lower="-3" upper="3" effort="0" velocity="0"/>
  </joint>
  <link name="l_foot_large">
    <visual>
      <geometry>
        <mesh filename="package://roid1_description/meshes/l_foot_large.stl"/>
      </geometry>
      <origin xyz="0 0 0"/>
      <material name="dark_gray"/>
    </visual>
  </link>


  <!--right side lower body-->

  <!--r_hipjoint_yaw-->
  <joint name="r_hipjoint_yaw" type="revolute">
    <parent link="c_waist"/>
    <child link="r_hipjoint_upper"/>
    <axis xyz="0 0 1"/>
    <origin xyz="0.0 -0.021530 -0.044936"/>
    <limit lower="-3" upper="3" effort="0" velocity="0"/>
  </joint>
  <link name="r_hipjoint_upper">
    <visual>
      <geometry>
        <mesh filename="package://roid1_description/meshes/r_hipjoint_upper.stl" />
      </geometry>
      <origin xyz="0 0 0"/>
      <material name="light_gray" />
    </visual>
    <visual>
      <geometry>
        <mesh filename="package://roid1_description/meshes/dec_r_hipjoint_upperpoint.stl" />
      </geometry>
      <origin xyz="0 0 0"/>
      <material name="orange"/>
    </visual>
  </link>

  <!--r_hipjoint_roll-->
  <joint name="r_hipjoint_roll" type="revolute">
    <parent link="r_hipjoint_upper"/>
    <child link="r_hipjoint_lower"/>
    <axis xyz="1 0 0"/>
    <origin xyz="0 0.004501 0"/>
    <limit lower="-3" upper="3" effort="0" velocity="0"/>
  </joint>
  <link name="r_hipjoint_lower">
    <visual>
      <geometry>
        <mesh filename="package://roid1_description/meshes/r_hipjoint_lower.stl" />
      </geometry>
      <origin xyz="0 0 0"/>
      <material name="dark_gray" />
    </visual>
  </link>

  <!--r_hipjoint_pitch-->
  <joint name="r_hipjoint_pitch" type="revolute">
    <parent link="r_hipjoint_lower"/>
    <child link="r_leg_upper"/>
    <axis xyz="0 1 0"/>
    <origin xyz="0.004052 -0.011504 -0.038476"/>
    <limit lower="-3" upper="3" effort="0" velocity="0"/>
  </joint>
  <link name="r_leg_upper">
    <visual>
      <geometry>
        <mesh filename="package://roid1_description/meshes/r_leg_upper_a.stl" />
      </geometry>
      <origin xyz="0 0 0"/>
      <material name="dark_gray" />
    </visual>
    <visual>
      <geometry>
        <mesh filename="package://roid1_description/meshes/r_leg_upper_b.stl" />
      </geometry>
      <origin xyz="0 0 0"/>
      <material name="light_gray" />
    </visual>
  </link>

  <!--r_knee_pitch-->
  <joint name="r_knee_pitch" type="revolute">
    <parent link="r_leg_upper"/>
    <child link="r_leg_lower"/>
    <axis xyz="0 1 0"/>
    <origin xyz="0.0 0.0 -0.065008"/>
    <limit lower="-3" upper="3" effort="0" velocity="0"/>
  </joint>
  <link name="r_leg_lower">
    <visual>
      <geometry>
        <mesh filename="package://roid1_description/meshes/r_leg_lower_a.stl" />
      </geometry>
      <origin xyz="0 0 0"/>
      <material name="dark_gray" />
    </visual>
    <visual>
      <geometry>
        <mesh filename="package://roid1_description/meshes/r_leg_lower_b.stl" />
      </geometry>
      <origin xyz="0 0 0"/>
      <material name="light_gray" />
    </visual>
  </link>

  <!--r_ankle_pitch-->
  <joint name="r_ankle_pitch" type="revolute">
    <parent link="r_leg_lower"/>
    <child link="r_ankle"/>
    <axis xyz="0 1 0"/>
    <origin xyz="0.0 0.0 -0.065203"/>
    <limit lower="-3" upper="3" effort="0" velocity="0"/>
  </joint>
  <link name="r_ankle">
    <visual>
      <geometry>
        <mesh filename="package://roid1_description/meshes/r_ankle.stl" />
      </geometry>
      <origin xyz="0 0 0"/>
      <material name="dark_gray" />
    </visual>
  </link>

  <!--r_ankle_roll-->
  <joint name="r_ankle_roll" type="revolute">
    <parent link="r_ankle"/>
    <child link="r_foot_large"/>
    <axis xyz="1 0 0"/>
    <origin xyz="0.0 0.011404 -0.038550"/>
    <limit lower="-3" upper="3" effort="0" velocity="0"/>
  </joint>
  <link name="r_foot_large">
    <visual>
      <geometry>
        <mesh filename="package://roid1_description/meshes/r_foot_large.stl" />
      </geometry>
      <origin xyz="0 0 0"/>
      <material name="dark_gray" />
    </visual>
  </link>




</robot>
