<?xml version="1.0"?>

<robot name="Roid1">

  <!--material color setting -->
  <material name="dark_gray">
    <color rgba="0.2 0.2 0.2 1.0" />
  </material>
  <material name="light_gray">
    <color rgba="0.99 0.99 0.99 1.0" />
  </material>
  <material name="light_blue">
    <color rgba="0.3 0.5 1.0 1.0" />
  </material>
  <material name="orange">
    <color rgba="1.0 0.3 0.1 1.0" />
  </material>

  <!--base link: origin of this model(0,0,0) -->
  <link name="base_footprint" />
  <link name="base_link">
    <inertial>
      <origin rpy="0 0 0" xyz="-0.0004860989233068058 0.009532810756286874 0.27413898086600197" />
      <mass value="0.13408213174666955" />
      <inertia ixx="6.3e-05" ixy="0.0" ixz="-0.0" iyy="3.6e-05" iyz="-0.0" izz="6.8e-05" />
    </inertial>
    <visual>
      <geometry>
        <mesh filename="package://roid1/URDF/roid1_description/meshes/c_waist.stl" />
      </geometry>
      <material name="dark_gray" />
    </visual>
    <collision>
      <geometry>
        <mesh filename="package://roid1/URDF/roid1_description/meshes/c_waist.stl" />
      </geometry>
    </collision>
  </link>

  <!--chest-->
  <joint name="c_chest_yaw" type="revolute">
    <parent link="base_link" />
    <child link="c_chest" />
    <axis xyz="0 0 1" />
    <origin xyz="0 0 0.065192" />
    <limit lower="-3" upper="3" effort="0" velocity="0" />
  </joint>

  <link name="c_chest">
    <inertial>
      <origin rpy="0 0 0" xyz="0.004546800382866728 -4.1161282904669805e-08 -0.0024788373011201403" />
      <mass value="0.033763915303500654" />
      <inertia ixx="3.4e-05" ixy="-0.0" ixz="-3e-06" iyy="1.9e-05" iyz="0.0" izz="3.6e-05" />
    </inertial>
    <visual>
      <geometry>
        <mesh filename="package://roid1/URDF/roid1_description/meshes/c_chest.stl" />
      </geometry>
      <origin xyz="0 0 0" />
      <material name="dark_gray" />
    </visual>
  </link>

  <joint name="c_chest_ab" type="fixed">
    <parent link="c_chest" />
    <child link="c_chest_b" />
    <origin xyz="0 0 0" />
    <limit lower="-3" upper="3" effort="0" velocity="0" />
  </joint>

  <link name="c_chest_b">
    <inertial>
      <origin rpy="0 0 0" xyz="-0.027362562372520854 2.840518613928325e-06 0.004477857770456339" />
      <mass value="0.08659748664099903" />
      <inertia ixx="0.000118" ixy="0.0" ixz="0.0" iyy="5.2e-05" iyz="0.0" izz="9.8e-05" />
    </inertial>
  </link>

  <joint name="c_chest_bc" type="fixed">
    <parent link="c_chest_b" />
    <child link="c_chest_c" />
    <origin xyz="0 0 0" />
    <limit lower="-3" upper="3" effort="0" velocity="0" />
  </joint>

  <link name="c_chest_c">
    <inertial>
      <origin rpy="0 0 0" xyz="-9.07564737343998e-05 -4.299695898109246e-08 0.04371354326547944" />
      <mass value="0.1751250442918052" />
      <inertia ixx="0.000158" ixy="0.0" ixz="0.0" iyy="6.6e-05" iyz="-0.0" izz="0.000176" />
    </inertial>
    <visual>
      <origin xyz="0 0 0" />
      <geometry>
        <mesh filename="package://roid1/URDF/roid1_description/meshes/c_chest_b.stl" />
      </geometry>
      <material name="light_gray" />
    </visual>
    <collision>
      <geometry>
        <mesh filename="package://roid1/URDF/roid1_description/meshes/c_chest_b.stl" />
      </geometry>
    </collision>
  </link>

  <!--head-->
  <joint name="c_head_yaw" type="revolute">
    <parent link="c_chest" />
    <child link="c_head" />
    <axis xyz="0 0 1" />
    <origin xyz="0 0 0.039505" />
    <limit lower="-3" upper="3" effort="0" velocity="0" />
  </joint>
  <link name="c_head">
    <inertial>
      <origin rpy="0 0 0" xyz="0.003079433021973575 -4.3073247395913894e-08 0.022888877386975093" />
      <mass value="0.012778861662402228" />
      <inertia ixx="2e-06" ixy="-0.0" ixz="-0.0" iyy="4e-06" iyz="0.0" izz="3e-06" />
    </inertial>
    <visual>
      <geometry>
        <mesh filename="package://roid1/URDF/roid1_description/meshes/c_head_a.stl" />
      </geometry>
      <origin xyz="0 0 0" />
      <material name="light_gray" />
    </visual>
    <visual>
      <geometry>
        <mesh filename="package://roid1/URDF/roid1_description/meshes/c_head_b.stl" />
      </geometry>
      <origin xyz="0 0 0" />
      <material name="light_blue" />
    </visual>
    <collision>
      <origin rpy="0 0 0" xyz="-0.022456 -0.009542 -0.35425" />
      <geometry>
        <mesh filename="package://roid1/URDF/roid1_description/meshes/c_head_a.stl" />
      </geometry>
    </collision>
  </link>


  <!--left side upper body-->

  <!--chest to l_shoulder-->
  <joint name="l_shoulder_pitch" type="revolute">
    <parent link="c_chest" />
    <child link="l_shoulder" />
    <axis xyz="0 1 0" />
    <origin xyz="0 0.074375 0" />
    <limit lower="-3" upper="3" effort="0" velocity="0" />
  </joint>
  <link name="l_shoulder">
    <inertial>
      <origin rpy="0 0 0" xyz="0.00016940373751364937 0.008747288709026461 3.2529534621517087e-14" />
      <mass value="0.012120367829212707" />
      <inertia ixx="1e-06" ixy="-0.0" ixz="0.0" iyy="4e-06" iyz="0.0" izz="4e-06" />
    </inertial>
    <visual>
      <origin xyz="0 0 0" />
      <geometry>
        <mesh filename="package://roid1/URDF/roid1_description/meshes/l_shoulder.stl" />
      </geometry>
      <origin xyz="0 0 0" />
      <material name="light_gray">
        <color rgba="0.8 0.8 0.8 1" />
      </material>
    </visual>
    <visual>
      <geometry>
        <mesh filename="package://roid1/URDF/roid1_description/meshes/dec_shoulderpoint.stl" />
      </geometry>
      <origin xyz="0 0 0" />
      <material name="orange" />
    </visual>
    <collision>
      <geometry>
        <mesh filename="package://roid1/URDF/roid1_description/meshes/l_shoulder.stl" />
      </geometry>
    </collision>
  </link>

  <!--l_shoulder_roll-->
  <joint name="l_shoulder_roll" type="revolute">
    <parent link="l_shoulder" />
    <child link="l_upperarm" />
    <axis xyz="1 0 0" />
    <origin xyz="0 0 0" />
    <limit lower="-3" upper="3" effort="0" velocity="0" />
  </joint>
  <link name="l_upperarm">
    <inertial>
      <origin rpy="0 0 0" xyz="-0.02256531849252991 -4.2996961130414846e-08 -0.03564584515249991" />
      <mass value="0.09077338253436838" />
      <inertia ixx="5.4e-05" ixy="0.0" ixz="-1e-05" iyy="6.4e-05" iyz="0.0" izz="1.8e-05" />
    </inertial>
    <visual>
      <geometry>
        <mesh filename="package://roid1/URDF/roid1_description/meshes/l_arm_upper.stl" />
      </geometry>
      <origin xyz="0 0 0" />
      <material name="dark_gray" />
    </visual>
    <collision>
      <geometry>
        <mesh filename="package://roid1/URDF/roid1_description/meshes/l_arm_upper.stl" />
      </geometry>
    </collision>
  </link>

  <!--l_elbow_yaw-->
  <joint name="l_elbow_yaw" type="revolute">
    <parent link="l_upperarm" />
    <child link="l_elbow" />
    <axis xyz="0 0 1" />
    <origin xyz="0.004449 0 -0.087511" />
    <limit lower="-3" upper="3" effort="0" velocity="0" />
  </joint>
  <link name="l_elbow">
    <inertial>
      <origin rpy="0 0 0" xyz="5.745484729775818e-05 -4.299695875731313e-08 -0.012574921301198305" />
      <mass value="0.044771268874731644" />
      <inertia ixx="6e-06" ixy="0.0" ixz="0.0" iyy="8e-06" iyz="-0.0" izz="1e-05" />
    </inertial>
    <visual>
      <geometry>
        <mesh filename="package://roid1/URDF/roid1_description/meshes/l_elbow.stl" />
      </geometry>
      <origin xyz="0.0 0 0" />
      <material name="dark_gray" />
    </visual>
    <collision>
      <geometry>
        <mesh filename="package://roid1/URDF/roid1_description/meshes/l_elbow.stl" />
      </geometry>
    </collision>
  </link>

  <!--l_elbow_pitch-->
  <joint name="l_elbow_pitch" type="revolute">
    <parent link="l_elbow" />
    <child link="l_lowerarm" />
    <axis xyz="0 1 0" />
    <origin xyz="0.004698 0 0" />
    <limit lower="-3" upper="3" effort="0" velocity="0" />
  </joint>
  <link name="l_lowerarm">
    <inertial>
      <origin rpy="0 0 0" xyz="0.00017641899363149416 -0.0156924274010031 -0.04569649848488025" />
      <mass value="0.02983803452815617" />
      <inertia ixx="1.8e-05" ixy="0.0" ixz="0.0" iyy="1.6e-05" iyz="-0.0" izz="4e-06" />
    </inertial>
    <visual>
      <geometry>
        <mesh filename="package://roid1/URDF/roid1_description/meshes/l_arm_lower.stl" />
      </geometry>
      <origin xyz="0 0 0" />
      <material name="light_gray" />
    </visual>
    <collision>
      <geometry>
        <mesh filename="package://roid1/URDF/roid1_description/meshes/l_arm_lower.stl" />
      </geometry>
    </collision>
  </link>


  <!--right side upper body-->

  <!--r_shoulder_pitch-->
  <joint name="r_shoulder_pitch" type="revolute">
    <parent link="c_chest" />
    <child link="r_shoulder" />
    <axis xyz="0 1 0" />
    <origin xyz="0 -0.074375 0" />
    <limit lower="-3" upper="3" effort="0" velocity="0" />
  </joint>
  <link name="r_shoulder">
    <inertial>
      <origin rpy="0 0 0" xyz="0.00016940373733528857 -0.008747374702943796 5.306866057708248e-14" />
      <mass value="0.01212036782921271" />
      <inertia ixx="1e-06" ixy="0.0" ixz="-0.0" iyy="4e-06" iyz="0.0" izz="4e-06" />
    </inertial>
    <visual>
      <geometry>
        <mesh filename="package://roid1/URDF/roid1_description/meshes/r_shoulder.stl" />
      </geometry>
      <origin xyz="0 0 0" />
      <material name="light_gray">
          <color rgba="0.8 0.8 0.8 1" />
      </material>
    </visual>
    <visual>
      <geometry>
        <mesh filename="package://roid1/URDF/roid1_description/meshes/dec_shoulderpoint.stl" />
      </geometry>
      <origin xyz="0 0 0" />
      <material name="orange" />
    </visual>
    <collision>
      <geometry>
        <mesh filename="package://roid1/URDF/roid1_description/meshes/r_shoulder.stl" />
      </geometry>
    </collision>
  </link>

  <!--r_shoulder_roll-->
  <joint name="r_shoulder_roll" type="revolute">
    <parent link="r_shoulder" />
    <child link="r_upperarm" />
    <axis xyz="1 0 0" />
    <origin xyz="0 0 0" />
    <limit lower="-3" upper="3" effort="0" velocity="0" />
  </joint>
  <link name="r_upperarm">
    <inertial>
      <origin rpy="0 0 0" xyz="-0.022565318492529688 -4.2996961074903695e-08 -0.03564584515249991" />
      <mass value="0.09077338253436838" />
      <inertia ixx="5.4e-05" ixy="0.0" ixz="-1e-05" iyy="6.4e-05" iyz="0.0" izz="1.8e-05" />
    </inertial>
    <visual>
      <geometry>
        <mesh filename="package://roid1/URDF/roid1_description/meshes/r_arm_upper.stl" />
      </geometry>
      <origin xyz="0 0 0" />
      <material name="dark_gray" />
    </visual>
    <collision>
      <geometry>
        <mesh filename="package://roid1/URDF/roid1_description/meshes/r_arm_upper.stl" />
      </geometry>
    </collision>
  </link>

  <!--r_elbow_yaw-->
  <joint name="r_elbow_yaw" type="revolute">
    <parent link="r_upperarm" />
    <child link="r_elbow" />
    <axis xyz="0 0 1" />
    <origin xyz="0.004449 0 -0.087511" />
    <limit lower="-3" upper="3" effort="0" velocity="0" />
  </joint>
  <link name="r_elbow">
    <inertial>
      <origin rpy="0 0 0" xyz="5.7454847330103836e-05 -4.2996958674046404e-08 -0.012574921301198305" />
      <mass value="0.044771268874731526" />
      <inertia ixx="6e-06" ixy="0.0" ixz="0.0" iyy="8e-06" iyz="-0.0" izz="1e-05" />
    </inertial>
    <visual>
      <geometry>
        <mesh filename="package://roid1/URDF/roid1_description/meshes/r_elbow.stl" />
      </geometry>
      <origin xyz="0.0 0 0" />
      <material name="dark_gray" />
    </visual>
    <collision>
      <geometry>
        <mesh filename="package://roid1/URDF/roid1_description/meshes/r_elbow.stl" />
      </geometry>
    </collision>
  </link>

  <!--r_elbow_pitch-->
  <joint name="r_elbow_pitch" type="revolute">
    <parent link="r_elbow" />
    <child link="r_lowerarm" />
    <axis xyz="0 1 0" />
    <origin xyz="0.004698 0 0" />
    <limit lower="-3" upper="3" effort="0" velocity="0" />
  </joint>
  <link name="r_lowerarm">
    <inertial>
      <origin rpy="0 0 0" xyz="0.00017641899364317232 0.01569234140705124 -0.04569649848495705" />
      <mass value="0.029838034528201704" />
      <inertia ixx="1.8e-05" ixy="-0.0" ixz="0.0" iyy="1.6e-05" iyz="0.0" izz="4e-06" />
    </inertial>
    <visual>
      <geometry>
        <mesh filename="package://roid1/URDF/roid1_description/meshes/r_arm_lower.stl" />
      </geometry>
      <origin xyz="0 0 0" />
      <material name="light_gray" />
    </visual>
    <collision>
      <geometry>
        <mesh filename="package://roid1/URDF/roid1_description/meshes/r_arm_lower.stl" />
      </geometry>
    </collision>
  </link>


  <!--left side lower body-->

  <!--l_hipjoint_yaw-->
  <joint name="l_hipjoint_yaw" type="revolute">
    <parent link="base_link" />
    <child link="l_hipjoint_upper" />
    <axis xyz="0 0 1" />
    <origin xyz="0.0 0.021530 -0.044936" />
    <limit lower="-3" upper="3" effort="0" velocity="0" />
  </joint>
  <link name="l_hipjoint_upper">
    <inertial>
      <origin rpy="0 0 0" xyz="3.293764515496962e-05 -0.0011113374509284651 -0.007400199793976242" />
      <mass value="0.005702042499396512" />
      <inertia ixx="1e-06" ixy="0.0" ixz="0.0" iyy="2e-06" iyz="-0.0" izz="2e-06" />
    </inertial>
    <visual>
      <geometry>
        <mesh filename="package://roid1/URDF/roid1_description/meshes/l_hipjoint_upper.stl" />
      </geometry>
      <origin xyz="0 0 0" />
      <material name="light_gray" />
    </visual>
    <visual>
      <geometry>
        <mesh filename="package://roid1/URDF/roid1_description/meshes/dec_l_hipjoint_upperpoint.stl" />
      </geometry>
      <origin xyz="0 0 0" />
      <material name="orange" />
    </visual>
    <collision>
      <geometry>
        <mesh filename="package://roid1/URDF/roid1_description/meshes/l_hipjoint_upper.stl" />
      </geometry>
    </collision>
  </link>

  <!--l_hipjoint_roll-->
  <joint name="l_hipjoint_roll" type="revolute">
    <parent link="l_hipjoint_upper" />
    <child link="l_hipjoint_lower" />
    <axis xyz="1 0 0" />
    <origin xyz="0 -0.004501 0" />
    <limit lower="-3" upper="3" effort="0" velocity="0" />
  </joint>
  <link name="l_hipjoint_lower" type="revolute"><!--need to fix-->
    <inertial>
      <origin rpy="0 0 0" xyz="-0.016250242301438553 0.011463181378816707 -0.0066539419866288585" />
      <mass value="0.06689532645492419" />
      <inertia ixx="2e-05" ixy="0.0" ixz="-0.0" iyy="1.4e-05" iyz="0.0" izz="1.5e-05" />
    </inertial>
    <visual>
      <geometry>
        <mesh filename="package://roid1/URDF/roid1_description/meshes/l_hipjoint_lower.stl" />
      </geometry>
      <origin xyz="0 0 0" />
      <material name="dark_gray" />
    </visual>
    <collision>
      <geometry>
        <mesh filename="package://roid1/URDF/roid1_description/meshes/l_hipjoint_lower.stl" />
      </geometry>
    </collision>
  </link>

  <!--l_hipjoint_pitch-->
  <joint name="l_hipjoint_pitch" type="revolute">
    <parent link="l_hipjoint_lower" />
    <child link="l_leg_upper" />
    <axis xyz="0 1 0" />
    <origin xyz="0.004052 0.011504 -0.038476" />
    <limit lower="-3" upper="3" effort="0" velocity="0" />
  </joint>
  <link name="l_leg_upper">
    <inertial>
      <origin rpy="0 0 0" xyz="0.002589780466551929 -0.016500042996958703 -0.03375567398425394" />
      <mass value="0.09097466003274825" />
      <inertia ixx="5.9e-05" ixy="0.0" ixz="4e-06" iyy="5.6e-05" iyz="0.0" izz="1.3e-05" />
    </inertial>
    <visual>
      <geometry>
        <mesh filename="package://roid1/URDF/roid1_description/meshes/l_leg_upper_a.stl" />
      </geometry>
      <origin xyz="0 0 0" />
      <material name="dark_gray" />
    </visual>
    <visual>
      <geometry>
        <mesh filename="package://roid1/URDF/roid1_description/meshes/l_leg_upper_b.stl" />
      </geometry>
      <origin xyz="0 0 0" />
      <material name="light_gray" />
    </visual>
    <collision>
      <geometry>
        <mesh filename="package://roid1/URDF/roid1_description/meshes/l_leg_upper_a.stl" />
      </geometry>
    </collision>
  </link>

  <!--l_knee_pitch-->
  <joint name="l_knee_pitch" type="revolute">
    <parent link="l_leg_upper" />
    <child link="l_leg_lower" />
    <axis xyz="0 1 0" />
    <origin xyz="0.0 0.0 -0.065008" />
    <limit lower="-3" upper="3" effort="0" velocity="0" />
  </joint>
  <link name="l_leg_lower">
    <inertial>
      <origin rpy="0 0 0" xyz="0.0044805681524230055 -0.015970110512676966 -0.04182100713444817" />
      <mass value="0.06094435150357522" />
      <inertia ixx="2.9e-05" ixy="0.0" ixz="-5e-06" iyy="2.6e-05" iyz="-0.0" izz="1.1e-05" />
    </inertial>
    <visual>
      <geometry>
        <mesh filename="package://roid1/URDF/roid1_description/meshes/l_leg_lower_a.stl" />
      </geometry>
      <origin xyz="0 0 0" />
      <material name="dark_gray" />
    </visual>
    <visual>
      <geometry>
        <mesh filename="package://roid1/URDF/roid1_description/meshes/l_leg_lower_b.stl" />
      </geometry>
      <origin xyz="0 0 0" />
      <material name="light_gray" />
    </visual>
    <collision>
      <geometry>
        <mesh filename="package://roid1/URDF/roid1_description/meshes/l_leg_lower_a.stl" />
      </geometry>
    </collision>
  </link>

  <!--l_ankle_pitch-->
  <joint name="l_ankle_pitch" type="revolute">
    <parent link="l_leg_lower" />
    <child link="l_ankle" />
    <axis xyz="0 1 0" />
    <origin xyz="0.0 0.0 -0.065203" />
    <limit lower="-3" upper="3" effort="0" velocity="0" />
  </joint>
  <link name="l_ankle">
    <inertial>
      <origin rpy="0 0 0" xyz="0.0001886240331466279 -0.01666391069306302 -0.03292964719213733" />
      <mass value="0.06757551562559608" />
      <inertia ixx="2e-05" ixy="0.0" ixz="0.0" iyy="1.4e-05" iyz="-0.0" izz="1.6e-05" />
    </inertial>
    <visual>
      <geometry>
        <mesh filename="package://roid1/URDF/roid1_description/meshes/l_ankle.stl" />
      </geometry>
      <origin xyz="0 0 0" />
      <material name="dark_gray" />
    </visual>
    <collision>
      <geometry>
        <mesh filename="package://roid1/URDF/roid1_description/meshes/l_ankle.stl" />
      </geometry>
    </collision>
  </link>

  <!--l_ankle_roll-->
  <joint name="l_ankle_roll" type="revolute">
    <parent link="l_ankle" />
    <child link="l_foot_large" />
    <axis xyz="1 0 0" />
    <origin xyz="0.0 -0.011404 -0.038550" />
    <limit lower="-3" upper="3" effort="0" velocity="0" />
  </joint>
  <link name="l_foot_large">  <!--need to fix-->
    <inertial>
      <origin rpy="0 0 0" xyz="-0.020700151207673705 0.023895172544662873 -0.021244534057561063" />
      <mass value="0.03847104970565043" />
      <inertia ixx="2.3e-05" ixy="-0.0" ixz="0.0" iyy="4.8e-05" iyz="0.0" izz="6.9e-05" />
    </inertial>
    <visual>
      <geometry>
        <mesh filename="package://roid1/URDF/roid1_description/meshes/l_foot_large.stl" />
      </geometry>
      <origin xyz="0 0 0" />
      <material name="dark_gray" />
    </visual>
    <collision>
      <geometry>
        <mesh filename="package://roid1/URDF/roid1_description/meshes/l_foot_large.stl" />
      </geometry>
    </collision>
  </link>


  <!--right side lower body-->

  <!--r_hipjoint_yaw-->
  <joint name="r_hipjoint_yaw" type="revolute">
    <parent link="base_link" />
    <child link="r_hipjoint_upper" />
    <axis xyz="0 0 1" />
    <origin xyz="0.0 -0.021530 -0.044936" />
    <limit lower="-3" upper="3" effort="0" velocity="0" />
  </joint>
  <link name="r_hipjoint_upper">
    <inertial>
      <origin rpy="0 0 0" xyz="3.2937645155054623e-05 0.0011112514569246185 -0.007400199793976325" />
      <mass value="0.005702042499396526" />
      <inertia ixx="1e-06" ixy="-0.0" ixz="0.0" iyy="2e-06" iyz="0.0" izz="2e-06" />
    </inertial>
    <visual>
      <geometry>
        <mesh filename="package://roid1/URDF/roid1_description/meshes/r_hipjoint_upper.stl" />
      </geometry>
      <origin xyz="0 0 0" />
      <material name="light_gray" />
    </visual>
    <visual>
      <geometry>
        <mesh filename="package://roid1/URDF/roid1_description/meshes/dec_r_hipjoint_upperpoint.stl" />
      </geometry>
      <origin xyz="0 0 0" />
      <material name="orange" />
    </visual>
    <collision>
      <geometry>
        <mesh filename="package://roid1/URDF/roid1_description/meshes/r_hipjoint_upper.stl" />
      </geometry>
    </collision>
  </link>

  <!--r_hipjoint_roll-->
  <joint name="r_hipjoint_roll" type="revolute">
    <parent link="r_hipjoint_upper" />
    <child link="r_hipjoint_lower" />
    <axis xyz="1 0 0" />
    <origin xyz="0 0.004501 0" />
    <limit lower="-3" upper="3" effort="0" velocity="0" />
  </joint>
  <link name="r_hipjoint_lower">
    <inertial>
      <origin rpy="0 0 0" xyz="-0.016250242301436166 -0.011463267372574608 -0.006653941986625556" />
      <mass value="0.0668953264549242" />
      <inertia ixx="2e-05" ixy="0.0" ixz="0.0" iyy="1.4e-05" iyz="-0.0" izz="1.5e-05" />
    </inertial>
    <visual>
      <geometry>
        <mesh filename="package://roid1/URDF/roid1_description/meshes/r_hipjoint_lower.stl" />
      </geometry>
      <origin xyz="0 0 0" />
      <material name="dark_gray" />
    </visual>
    <collision>
      <geometry>
        <mesh filename="package://roid1/URDF/roid1_description/meshes/r_hipjoint_lower.stl" />
      </geometry>
    </collision>
  </link>

  <!--r_hipjoint_pitch-->
  <joint name="r_hipjoint_pitch" type="revolute">
    <parent link="r_hipjoint_lower" />
    <child link="r_leg_upper" />
    <axis xyz="0 1 0" />
    <origin xyz="0.004052 -0.011504 -0.038476" />
    <limit lower="-3" upper="3" effort="0" velocity="0" />
  </joint>
  <link name="r_leg_upper">
    <inertial>
      <origin rpy="0 0 0" xyz="0.0025897804665520278 0.016499957003041386 -0.03375567398425397" />
      <mass value="0.09097466003274823" />
      <inertia ixx="5.9e-05" ixy="-0.0" ixz="4e-06" iyy="5.6e-05" iyz="0.0" izz="1.3e-05" />
    </inertial>
    <visual>
      <geometry>
        <mesh filename="package://roid1/URDF/roid1_description/meshes/r_leg_upper_a.stl" />
      </geometry>
      <origin xyz="0 0 0" />
      <material name="dark_gray" />
    </visual>
    <visual>
      <geometry>
        <mesh filename="package://roid1/URDF/roid1_description/meshes/r_leg_upper_b.stl" />
      </geometry>
      <origin xyz="0 0 0" />
      <material name="light_gray" />
    </visual>
    <collision>
      <geometry>
        <mesh filename="package://roid1/URDF/roid1_description/meshes/r_leg_upper_a.stl" />
      </geometry>
    </collision>
  </link>

  <!--r_knee_pitch-->
  <joint name="r_knee_pitch" type="revolute">
    <parent link="r_leg_upper" />
    <child link="r_leg_lower" />
    <axis xyz="0 1 0" />
    <origin xyz="0.0 0.0 -0.065008" />
    <limit lower="-3" upper="3" effort="0" velocity="0" />
  </joint>
  <link name="r_leg_lower">
    <inertial>
      <origin rpy="0 0 0" xyz="0.004480568152423165 0.01597002451875967 -0.04182100713444818" />
      <mass value="0.06094435150357523" />
      <inertia ixx="2.9e-05" ixy="-0.0" ixz="-5e-06" iyy="2.6e-05" iyz="0.0" izz="1.1e-05" />
    </inertial>
    <visual>
      <geometry>
        <mesh filename="package://roid1/URDF/roid1_description/meshes/r_leg_lower_a.stl" />
      </geometry>
      <origin xyz="0 0 0" />
      <material name="dark_gray" />
    </visual>
    <visual>
      <geometry>
        <mesh filename="package://roid1/URDF/roid1_description/meshes/r_leg_lower_b.stl" />
      </geometry>
      <origin xyz="0 0 0" />
      <material name="light_gray" />
    </visual>
    <collision>
      <geometry>
        <mesh filename="package://roid1/URDF/roid1_description/meshes/r_leg_lower_a.stl" />
      </geometry>
    </collision>
  </link>

  <!--r_ankle_pitch-->
  <joint name="r_ankle_pitch" type="revolute">
    <parent link="r_leg_lower" />
    <child link="r_ankle" />
    <axis xyz="0 1 0" />
    <origin xyz="0.0 0.0 -0.065203" />
    <limit lower="-3" upper="3" effort="0" velocity="0" />
  </joint>
  <link name="r_ankle">
    <inertial>
      <origin rpy="0 0 0" xyz="0.00018862403314765484 0.01666382469921859 -0.03292964719213813" />
      <mass value="0.06757551562559609" />
      <inertia ixx="2e-05" ixy="-0.0" ixz="0.0" iyy="1.4e-05" iyz="0.0" izz="1.6e-05" />
    </inertial>
    <visual>
      <geometry>
        <mesh filename="package://roid1/URDF/roid1_description/meshes/r_ankle.stl" />
      </geometry>
      <origin xyz="0 0 0" />
      <material name="dark_gray" />
    </visual>
    <collision>
      <geometry>
        <mesh filename="package://roid1/URDF/roid1_description/meshes/r_ankle.stl" />
      </geometry>
    </collision>
  </link>

  <!--r_ankle_roll-->
  <joint name="r_ankle_roll" type="revolute">
    <parent link="r_ankle" />
    <child link="r_foot_large" />
    <axis xyz="1 0 0" />
    <origin xyz="0.0 0.011404 -0.038550" />
    <limit lower="-3" upper="3" effort="0" velocity="0" />
  </joint>
  <link name="r_foot_large">
    <inertial>
      <origin rpy="0 0 0" xyz="-0.020700151207566492 -0.023895258538579878 -0.02124453405755709" />
      <mass value="0.03847104970565037" />
      <inertia ixx="2.3e-05" ixy="-0.0" ixz="-0.0" iyy="4.8e-05" iyz="-0.0" izz="6.9e-05" />
    </inertial>
    <visual>
      <geometry>
        <mesh filename="package://roid1/URDF/roid1_description/meshes/r_foot_large.stl" />
      </geometry>
      <origin xyz="0 0 0" />
      <material name="dark_gray" />
    </visual>
    <collision>
      <geometry>
        <mesh filename="package://roid1/URDF/roid1_description/meshes/r_foot_large.stl" />
      </geometry>
    </collision>
  </link>

</robot>
